Workbook

Sheet 📖 Introduction
A1: 📊 EXCEL DASHBOARDS — COMPLETE TUTORIAL
A2: Learn to build 5 professional Excel dashboards from scratch using real employee data
A4: # | B4: Dashboard Name | C4: What You'll Analyze | D4: Charts Used
A5: 1 | B5: HR Overview | C5: Gender, salary, education, top roles | D5: Pie + Bar + KPI Cards
A6: 2 | B6: Salary Analysis | C6: Payroll, salary ranges, top earners | D6: Column + Bar + Table
A7: 3 | B7: Demographics | C7: Age groups, gender split, education mix | D7: Stacked Bar + Pie
A8: 4 | B8: Job Title | C8: Headcount by role, gender per role | D8: Horizontal Bar + Cluster
A9: 5 | B9: Tenure & Hiring | C9: Hiring trend, tenure buckets, longevity | D9: Line + Pie + Column
A10: 6 | B10: Employee Performance & Insights | C10: Salary bands, top roles, gender×edu, age-salary trend | D10: Column + Horizontal Bar + Clustered + Line
A11: 📋 EXCEL SKILLS YOU WILL LEARN IN THIS TUTORIAL
A12: ✅ COUNTIF / COUNTIFS | C12: Count cells that meet one or more conditions
A13: ✅ AVERAGEIF / AVERAGEIFS | C13: Average values based on conditions
A14: ✅ SUMIF / SUMIFS | C14: Sum values based on conditions
A15: ✅ Pivot Tables | C15: Summarize and group large datasets instantly
A16: ✅ Pivot Charts | C16: Create charts linked to Pivot Tables
A17: ✅ Conditional Formatting | C17: Highlight data with colors, data bars, icons
A18: ✅ Named Ranges | C18: Give names to cell ranges for easy formulas
A19: ✅ Data Validation | C19: Create dropdown lists for data entry
A20: ✅ Chart Formatting | C20: Customize titles, colors, labels on charts
A21: ✅ Freeze Panes | C21: Lock rows/columns while scrolling
A22: ✅ VLOOKUP / XLOOKUP | C22: Lookup values from other sheets
A23: ✅ IF / IFS Statements | C23: Logical formulas for categorization
... A26: ✅ Dashboard Layout Design | C26: Arrange KPI cards, charts, and tables professionally

Sheet 📐 Excel Basics
A1: 📐 EXCEL BASICS & ESSENTIAL FORMULAS
A2: Master these core Excel skills before building dashboards
A4: 🔢 COUNTING & STATISTICAL FORMULAS
B5: Formula | C5: Syntax | D5: Example | E5: What it Does
B6: COUNT | C6: COUNT(range) | D6: =COUNT(G2:G916) | E6: Counts numeric cells
B7: COUNTA | C7: COUNTA(range) | D7: =COUNTA(A2:A916) | E7: Counts non-empty cells — use for names/text
B8: COUNTIF | C8: COUNTIF(range, criteria) | D8: =COUNTIF(C:C,"Male") | E8: Count cells matching one condition
B9: COUNTIFS | C9: COUNTIFS(r1,c1,r2,c2,...) | D9: =COUNTIFS(C:C,"Male",F:F,"Manager") | E9: Count cells matching multiple conditions
B10: SUM | C10: SUM(range) | D10: =SUM(G2:G916) | E10: Add all numbers in a range
B11: SUMIF | C11: SUMIF(range, criteria, sum_range) | D11: =SUMIF(C:C,"Female",G:G) | E11: Sum values where condition is met
B12: AVERAGE | C12: AVERAGE(range) | D12: =AVERAGE(G2:G916) | E12: Calculate average/mean
B13: AVERAGEIF | C13: AVERAGEIF(range, criteria, avg_range) | D13: =AVERAGEIF(F:F,"Engineer",G:G) | E13: Average where condition is met
B14: MAX | C14: MAX(range) | D14: =MAX(G2:G916) | E14: Find the largest value
B15: MIN | C15: MIN(range) | D15: =MIN(G2:G916) | E15: Find the smallest value
B16: MEDIAN | C16: MEDIAN(range) | D16: =MEDIAN(G2:G916) | E16: Find the middle value
B17: STDEV | C17: STDEV(range) | D17: =STDEV(G2:G916) | E17: Measure how spread out salaries are
A19: 🔍 LOOKUP FORMULAS
B20: Formula | C20: Syntax | D20: Example | E20: What it Does
B21: VLOOKUP | C21: VLOOKUP(lookup, table, col_index, FALSE) | D21: =VLOOKUP("EMP001",A:H,7,FALSE) | E21: Find a value by matching an ID
B22: XLOOKUP | C22: XLOOKUP(lookup, lookup_arr, return_arr) | D22: =XLOOKUP(A2,EmpData!A:A,EmpData!G:G) | E22: Modern replacement for VLOOKUP (Excel 2019+)
B23: INDEX+MATCH | C23: INDEX(return_range, MATCH(lookup,range,0)) | D23: =INDEX(G:G,MATCH("EMP001",B:B,0)) | E23: Flexible 2-way lookup
A25: 🔤 TEXT & LOGICAL FORMULAS
B26: Formula | C26: Syntax | D26: Example | E26: What it Does
B27: IF | C27: IF(condition, if_true, if_false) | D27: =IF(G2>100000,"Senior","Junior") | E27: Categorize based on a condition
B28: IFS | C28: IFS(cond1,val1,cond2,val2,...) | D28: =IFS(H2<30,"Young",H2<50,"Mid",TRUE,"Senior") | E28: Multiple conditions without nesting IF
B29: TEXT | C29: TEXT(value, format_text) | D29: =TEXT(G2,"$#,##0.00") | E29: Format a number as text
B30: LEFT/RIGHT | C30: LEFT(text, num_chars) | D30: =LEFT(A2, 5) | E30: Extract characters from left/right of text
B31: UPPER/LOWER | C31: UPPER(text) | D31: =UPPER(C2) | E31: Convert text to uppercase/lowercase
B32: TRIM | C32: TRIM(text) | D32: =TRIM(A2) | E32: Remove extra spaces from text
B33: CONCATENATE | C33: CONCAT(text1, text2,...) | D33: =CONCAT(A2," - ",F2) | E33: Join text from multiple cells

Sheet 🏢 D1 - HR Overview
A1: 🏢 DASHBOARD 1: HR OVERVIEW — Step-by-Step Tutorial
A2: Goal: Build a complete HR dashboard with KPI cards, gender pie, salary bar, and education chart
A4: PHASE 1: PREPARE YOUR DATA
A5: Step 1 | B5: Open Employee Data | C5: Open employee_data.xlsx. Make sure you see 8 columns: Name, Emp ID, Gender, Education, Date of Join, Job Title, Salary, Age | E5: Data is ready ✅
A6: Step 2 | B6: Format as Table | C6: Select A1:H916 → Press Ctrl+T → Check 'My table has headers' → Click OK | E6: Excel adds filters + zebra stripes ✅
A7: Step 3 | B7: Freeze Top Row | C7: View tab → Freeze Panes → Freeze Top Row Now the header stays visible as you scroll | E7: Row 1 stays locked ✅
A8: Step 4 | B8: Format Salary Column | C8: Select column G (Salary) → Right-click → Format Cells → Currency → 2 decimal places → OK | E8: Salary shows as $41,923.37 ✅
A9: 💡 TIP: Turning data into a Table (Ctrl+T) makes formulas auto-expand when you add rows and enables slicers for dashboards!
A11: PHASE 2: CREATE SUMMARY SHEET
A12: Step 5 | B12: New Summary Sheet | C12: Right-click a sheet tab → Insert → Worksheet Rename it 'Summary' by double-clicking the tab | E12: New sheet created ✅
A13: Step 6 | B13: Gender Count Formula | C13: In Summary!A1 type 'Gender', B1 type 'Count' A2: Male, A3: Female B2: =COUNTIF('Employee Data'!C:C,"Male") B3: =COUNTIF('Employee Data'!C:C,"Female") | D13: =COUNTIF('Employee Data'!C:C,"Male") | E13: Male: 450, Female: 466 ✅
A14: Step 7 | B14: Job Title Avg Salary | C14: D1: Job Title, E1: Avg Salary For each role, use AVERAGEIF: E2: =AVERAGEIF('Employee Data'!F:F,D2,'Employee Data'!G:G) | D14: =AVERAGEIF('Employee Data'!F:F,D2,'Employee Data'!G:G) | E14: Returns avg salary per role ✅
A15: Step 8 | B15: Education Count | C15: G1: Education, H1: Count List each education type in G2:G6 H2: =COUNTIF('Employee Data'!D:D,G2) Copy H2 down to H6 | D15: =COUNTIF('Employee Data'!D:D,G2) | E15: Count per education level ✅
A16: 💡 TIP: Always build summary sheets that feed your charts. Never link charts directly to raw data with thousands of rows.
A18: PHASE 3: CREATE KPI CARDS
A19: Step 9 | B19: Create Dashboard Sheet | C19: Create a new sheet called 'HR Dashboard' Right-click → Sheet Properties → Tab Color → choose dark blue | E19: Dashboard tab created ✅
A20: Step 10 | B20: Hide Gridlines | C20: View tab → uncheck 'Gridlines' This makes your dashboard look clean and professional | E20: Gridlines hidden ✅
A21: Step 11 | B21: Merge KPI Title Cells | C21: Select A4:B4 → Home → Merge & Center Type 'Total Employees' Select A5:B5 → Merge & Center Type formula: =COUNTA('Employee Data'!A:A)-1 | D21: =COUNTA('Employee Data'!A:A)-1 | E21: Shows 916 ✅
A22: Step 12 | B22: Style KPI Cards | C22: Fill KPI cells with dark blue: #1B4F72 Font: White, bold, size 18 for the value Font: White, bold, size 10 for the label Border: thin border around the card | E22: Professional KPI card ✅
A23: Step 13 | B23: Create 5 More KPIs | C23: Repeat for: Avg Salary, Avg Age, Total Payroll, Male Count, Female Count Formulas: Avg Salary: =AVERAGE('Employee Data'!G:G) Total Payroll: =SUM('Employee Data'!G:G) | D23: =AVERAGE('Employee Data'!G:G) | E23: All 6 KPIs displayed ✅
A24: 💡 TIP: Use the Format Painter (Ctrl+Shift+C / Ctrl+Shift+V) to quickly copy cell formatting from one KPI card to another!
A26: PHASE 4: INSERT CHARTS
A27: Step 14 | B27: Insert Pie Chart (Gender) | C27: Go to Summary sheet → Select A1:B3 (Gender + Count) Insert tab → Charts → Pie → 2D Pie Click the chart → Chart Design → Move Chart → 'HR Dashboard' sheet | E27: Pie chart inserted ✅
A28: Step 15 | B28: Format Pie Chart | C28: Click the chart title → rename: 'Gender Distribution' Right-click pie slices → Add Data Labels → Show Percentage+Category Chart Design → Change Colors → choose a color scheme | E28: Chart looks professional ✅
A29: Step 16 | B29: Insert Bar Chart (Salary by Role) | C29: Back to Summary, select D1:E11 (top 10 jobs + salaries) Insert → Bar Chart → Clustered Bar Move to HR Dashboard → resize to fill columns E-J | E29: Salary bar chart inserted ✅
A30: Step 17 | B30: Insert Column Chart (Education) | C30: Select G1:H6 on Summary sheet Insert → Column Chart → 2D Clustered Column Move to HR Dashboard → position below KPI cards | E30: Education chart inserted ✅
A31: Step 18 | B31: Final Layout | C31: Arrange: KPI cards on top row, Pie chart left, Bar chart right Add a title: Merge A1:L1 → type 'HR OVERVIEW DASHBOARD' Fill dark blue, white text, font size 20 | E31: Professional dashboard! ✅
A32: 💡 TIP: Resize charts by dragging corner handles. Hold Alt while dragging to snap the chart borders to cell boundaries!

Sheet 💰 D2 - Salary
A1: 💰 DASHBOARD 2: SALARY ANALYSIS — Step-by-Step Tutorial
A2: Goal: Analyze salary distribution, top earners, gender pay gap, and education vs pay
A4: STEP 1: CREATE SALARY RANGE BUCKETS
A5: Step 1 | B5: Create Salary Ranges | C5: In a new 'Salary Summary' sheet: A1: Salary Range, B1: Count A2: < $30K, A3: $30K-$60K, A4: $60K-$90K A5: $90K-$120K, A6: $120K+ | E5: Labels ready ✅
A6: Step 2 | B6: COUNTIFS for Ranges | C6: B2: =COUNTIFS('Employee Data'!G:G,">=0",'Employee Data'!G:G,"<30000") B3: =COUNTIFS('Employee Data'!G:G,">=30000",'Employee Data'!G:G,"<60000") Continue for each range... | D6: =COUNTIFS('Employee Data'!G:G,">=0",'Employee Data'!G:G,"<30000") | E6: Counts per range ✅
A7: Step 3 | B7: Gender Pay Gap | C7: D1: Gender, E1: Avg Salary D2: Male, D3: Female E2: =AVERAGEIF('Employee Data'!C:C,"Male",'Employee Data'!G:G) E3: =AVERAGEIF('Employee Data'!C:C,"Female",'Employee Data'!G:G) | D7: =AVERAGEIF('Employee Data'!C:C,"Male",'Employee Data'!G:G) | E7: Shows pay gap ✅
A8: Step 4 | B8: Top 15 Earners Table | C8: Create a LARGE or SORT formula: Use: =LARGE('Employee Data'!G:G, ROW()-1) Or manually sort by salary descending Copy top 15 rows to a new range | D8: =LARGE('Employee Data'!G:G,1) | E8: Top salaries listed ✅
A9: Step 5 | B9: Education vs Salary | C9: List all 5 education types For each: =AVERAGEIF('Employee Data'!D:D,K2,'Employee Data'!G:G) This shows if MBA earns more than Bachelor's Degree | D9: =AVERAGEIF('Employee Data'!D:D,K2,'Employee Data'!G:G) | E9: Education pay levels ✅
A10: 💡 TIP: COUNTIFS is your most powerful counting tool. It can count rows meeting ANY number of conditions simultaneously!
A12: STEP 2: BUILD SALARY CHARTS
A13: Step 6 | B13: Salary Distribution Chart | C13: Select Salary Range + Count (A1:B6) Insert → Column Chart → Clustered Column Title: 'Salary Distribution' Format data bars with gradient fill from green to red | E13: Distribution visible ✅
A14: Step 7 | B14: Gender Pay Gap Bar | C14: Select D1:E3 (Gender + Avg Salary) Insert → Bar Chart Add data labels to show exact $ amounts Color Male bars = blue, Female bars = pink/purple | E14: Pay gap visualized ✅
A15: Step 8 | B15: Education Salary Bar | C15: Select K1:L6 (Education + Avg Salary) Insert → Bar Chart → Horizontal Sort bars by value: Right-click → Sort → Highest to Lowest Title: 'Avg Salary by Education' | E15: Education ranking ✅
A16: 💡 TIP: To add $ data labels on charts: Click chart → + button (Chart Elements) → Data Labels → More Options → Number Format → Currency
A18: STEP 3: CONDITIONAL FORMATTING
A19: Step 9 | B19: Color Scale on Salaries | C19: Select all salary values on dashboard table Home → Conditional Formatting → Color Scales Choose: Red-Yellow-Green (low=red, high=green) Now you instantly see high vs low salaries! | E19: Color gradient applied ✅
A20: Step 10 | B20: Data Bars on Count Column | C20: Select the Count column in salary ranges Home → Conditional Formatting → Data Bars → Blue Bars grow wider for higher counts — like a mini chart in cells! | E20: Data bars applied ✅
A21: Step 11 | B21: Icon Sets for Ranking | C21: Select the salary values in top-15 table Home → Conditional Formatting → Icon Sets → 3 Arrows Green up arrow = high, yellow sideways = medium, red down = low | E21: Icons applied ✅
A22: 💡 TIP: Conditional Formatting is one of Excel's most powerful features! Use it to highlight outliers, top performers, and trends without any charts.

Sheet 👥 D3 - Demographics
A1: 👥 DASHBOARD 3: DEMOGRAPHICS — Step-by-Step Tutorial
A2: Goal: Visualize age distribution, gender ratios, and education profiles of the workforce
A4: STEP 1: AGE GROUP ANALYSIS
A5: Step 1 | B5: Create Age Group Column | C5: In Employee Data sheet, add column I: 'Age Group' I2: =IF(H2<30,"20s",IF(H2<40,"30s",IF(H2<50,"40s",IF(H2<60,"50s","60+")))) Drag down to all rows | D5: =IF(H2<30,"20s",IF(H2<40,"30s",IF(H2<50,"40s","50+"))) | E5: Age group labels ✅
A6: Step 2 | B6: Count by Age Group | C6: In Summary sheet: A1: Age Group, B1: Count A2:A6 → type the groups: 20-29, 30-39, 40-49, 50-59, 60+ B2: =COUNTIFS('Employee Data'!H:H,">=20",'Employee Data'!H:H,"<30") | D6: =COUNTIFS('Employee Data'!H:H,">=20",'Employee Data'!H:H,"<30") | E6: Age distribution ✅
A7: Step 3 | B7: Gender Split by Age | C7: Build a 2-column table: Male 20s: =COUNTIFS(C:C,"Male",H:H,">=20",H:H,"<30") Female 20s: =COUNTIFS(C:C,"Female",H:H,">=20",H:H,"<30") Repeat for each age group | D7: =COUNTIFS(C:C,"Male",H:H,">=20",H:H,"<30") | E7: Gender+age matrix ✅
A8: Step 4 | B8: Education Distribution | C8: Count each education level: =COUNTIF('Employee Data'!D:D,"Bachelor's Degree") =COUNTIF('Employee Data'!D:D,"MBA") Etc. for Diploma, Associate's, PhD | D8: =COUNTIF('Employee Data'!D:D,D2) | E8: Education counts ✅
A9: 💡 TIP: Nested IF formula tip: Excel allows up to 64 nested IFs, but use IFS() instead for cleaner, easier-to-read formulas in Excel 2019+!
A11: STEP 2: STACKED BAR CHART (KEY SKILL!)
A12: Step 5 | B12: Select Gender+Age Data | C12: Select your gender-by-age-group table (3 columns: Age, Male, Female) This gives us the data for a stacked bar | E12: Data selected ✅
A13: Step 6 | B13: Insert Stacked Bar | C13: Insert tab → Bar Chart → Stacked Column This stacks Male + Female on the same bar Total bar height = total employees in that age group | E13: Stacked chart inserted ✅
A14: Step 7 | B14: Add Chart Title + Legend | C14: Click chart title → type 'Gender Split by Age Group' Chart Elements (+) → check Legend → position at Bottom This shows which color = Male, which = Female | E14: Title + legend added ✅
A15: Step 8 | B15: Change Series Colors | C15: Click on Male bars → right-click → Format Data Series → Fill → Solid Fill → choose Blue (#2E86C1) Click Female bars → choose Purple (#7D3C98) | E15: Colors assigned ✅
A16: Step 9 | B16: Format Value Axis | C16: Click Y-axis numbers → right-click → Format Axis Set minimum: 0, Maximum: auto Number format: 0 (no decimals for count data) | E16: Clean axis labels ✅
A17: 💡 TIP: Stacked charts are perfect for showing part-to-whole relationships. Use 100% stacked bars when you want to compare proportions across groups!

Sheet 💼 D4 - Job Title
A1: 💼 DASHBOARD 4: JOB TITLE — Step-by-Step Tutorial
A2: Goal: Analyze headcount by role, identify salary leaders, and visualize gender mix per job
A4: STEP 1: PIVOT TABLE (THE EXCEL SUPERPOWER)
A5: Step 1 | B5: Create a Pivot Table | C5: Click anywhere in Employee Data → Insert tab → PivotTable Choose 'New Worksheet' → Click OK A blank Pivot Table appears with a field list on the right | E5: Pivot Table ready ✅
A6: Step 2 | B6: Configure Pivot Table | C6: From the field list on the right: → Drag 'Job Title' to ROWS → Drag 'Salary' to VALUES (it auto-sums) → Drag 'Name' to VALUES (change to Count) Now you have headcount + total salary per job! | E6: Pivot configured ✅
A7: Step 3 | B7: Change to Average Salary | C7: Click 'Sum of Salary' in the VALUES box → Value Field Settings → Summarize by: Average → OK Now it shows AVERAGE salary per job title (not sum) | E7: Avg salary per role ✅
A8: Step 4 | B8: Sort Pivot Table | C8: Click any cell in the Count column Data tab → Sort Largest to Smallest Now top job titles by headcount are at the top | E8: Sorted by headcount ✅
A9: Step 5 | B9: Insert Pivot Chart | C9: Click anywhere in your Pivot Table Insert tab → PivotChart → Bar Chart (horizontal) This chart auto-updates when data changes! | E9: Pivot Chart created ✅
A10: 💡 TIP: Pivot Tables are Excel's #1 data analysis tool! They summarize thousands of rows in seconds. Right-click → Refresh to update after data changes.
A12: STEP 2: SLICERS — INTERACTIVE FILTERING
A13: Step 6 | B13: Add a Slicer | C13: Click inside your Pivot Table PivotTable Analyze tab → Insert Slicer Check: Gender → OK A clickable gender filter button appears! | E13: Slicer inserted ✅
A14: Step 7 | B14: Style the Slicer | C14: Click the slicer Slicer tab → choose a slicer style (colors) Resize by dragging corners Position it neatly next to your chart on the dashboard | E14: Slicer styled ✅
A15: Step 8 | B15: Connect to Multiple Charts | C15: If you have 2 Pivot Charts from the same data: Right-click slicer → Report Connections Check both Pivot Tables → OK Now one click filters ALL charts! | E15: Slicer controls all charts ✅
A16: Step 9 | B16: Add Education Slicer | C16: Repeat: Insert Slicer → Check 'Education' Now you can filter by both Gender AND Education Click Male + Bachelor's → charts update instantly! | E16: Interactive dashboard! ✅
A17: 💡 TIP: Slicers transform a static dashboard into an interactive one! They're the easiest way to add filtering without any code.

Sheet 📅 D5 - Tenure
A1: 📅 DASHBOARD 5: TENURE & HIRING TRENDS — Step-by-Step Tutorial
A2: Goal: Track hiring history, analyze employee tenure, and find retention patterns
A4: STEP 1: DATE FUNCTIONS & TENURE CALCULATION
A5: Step 1 | B5: Extract Year from Date | C5: Add a new column 'Join Year' in Employee Data I2: =YEAR(E2) [if E is Date of Join] Drag down to all 916 rows Now you can count hires per year! | D5: =YEAR(E2) | E5: Year extracted ✅
A6: Step 2 | B6: Calculate Tenure in Years | C6: Add column 'Tenure Years': J2: =DATEDIF(E2,TODAY(),"Y") OR: J2: =INT((TODAY()-E2)/365.25) This gives years of service for each employee | D6: =DATEDIF(E2,TODAY(),"Y") | E6: Tenure calculated ✅
A7: Step 3 | B7: Tenure Category with IF | C7: Add column 'Tenure Group': K2: =IFS(J2<1,"< 1 Year",J2<3,"1-3 Years", J2<5,"3-5 Years",J2<10,"5-10 Years",TRUE,"10+ Years") Drag down to all rows | D7: =IFS(J2<1,"New",J2<3,"Junior",J2<5,"Mid",TRUE,"Senior") | E7: Tenure groups labeled ✅
A8: Step 4 | B8: Count Hires by Year | C8: In Summary sheet: F1: Year, G1: Hires List years: 2000, 2001, ..., 2024 G2: =COUNTIF('Employee Data'!I:I, F2) Drag formula down for all years | D8: =COUNTIF('Employee Data'!I:I,F2) | E8: Annual hire counts ✅
A9: Step 5 | B9: Avg Salary by Tenure | C9: H1: Tenure Group, I1: Avg Salary List tenure groups in H2:H6 I2: =AVERAGEIF('Employee Data'!K:K,H2,'Employee Data'!G:G) Drag down — shows if longer tenure = higher pay | D9: =AVERAGEIF('Employee Data'!K:K,H2,'Employee Data'!G:G) | E9: Tenure vs pay revealed ✅
A10: 💡 TIP: DATEDIF is a hidden Excel function — it's not in autocomplete! It calculates difference between dates in Years, Months, or Days.
A12: STEP 2: LINE CHART FOR TRENDS
A13: Step 6 | B13: Select Year & Hires Data | C13: Select your Year column + Hires column (F1:G25 or however many years) Include headers in selection | E13: Data selected ✅
A14: Step 7 | B14: Insert Line Chart | C14: Insert tab → Line Chart → Line with Markers This creates a timeline showing hiring spikes and dips The X-axis should show years automatically | E14: Line chart created ✅
A15: Step 8 | B15: Format the Line Chart | C15: Click the line → right-click → Format Data Series → Line color: your brand color → Marker: circle, size 8, matching color → Smooth line option: check for curvy look | E15: Line formatted ✅
A16: Step 9 | B16: Add a Trendline | C16: Click on the line in the chart → right-click → Add Trendline → Linear Check 'Display equation on chart' This shows the hiring trend direction (up or down over time) | E16: Trendline added ✅
A17: Step 10 | B17: Label Peak Year | C17: Click a data point → right-click → Add Data Label For the highest point, the year + count shows You can drag the label to a better position | E17: Peak year labeled ✅
A18: 💡 TIP: Line charts are best for showing trends over time. Always put time (years/months) on the X-axis and the measure (count/value) on the Y-axis.

Sheet 🧑‍💼 D6 - Employee
A1: 🧑‍💼 DASHBOARD 6: EMPLOYEE PERFORMANCE & INSIGHTS — Step-by-Step Tutorial
A2: Goal: Build a full employee insights dashboard with salary bands, top roles, gender×education mix, and age-salary trend
A3: 📋 WHAT YOU'LL BUILD IN THIS DASHBOARD
A4: 🟠 7 KPI Cards | C4: Headcount, Avg Salary, Total Payroll, Max Salary, Avg Age, Top Education, Gender Ratio
A5: 📊 Salary Band Chart | C5: Column chart showing how many employees fall in each salary band
A6: 📊 Top 10 Roles Chart | C6: Horizontal bar showing highest-paying job titles
A7: 📊 Gender × Education | C7: Clustered column comparing Male/Female per education level
A8: 📈 Age vs Salary Trend | C8: Line chart revealing how average salary changes with age
A9: 📋 Salary Band Detail Table | C9: Summary table with count, avg, min, max salary per band
A10: PHASE 1: BUILD THE SUMMARY DATA SHEET
A11: Step | B11: Action | C11: Instructions | D11: Formula | E11: Result
A12: Step 1 | B12: Create Summary Sheet | C12: Right-click any tab → Insert → Worksheet Rename to 'Summary Data' (double-click tab) | E12: New sheet ready ✅
A13: Step 2 | B13: Define Salary Bands | C13: In Summary Data, enter band labels in A2:A6: Entry (< $40K) Junior ($40K–$70K) Mid ($70K–$100K) Senior ($100K–$130K) Lead ($130K+) | E13: Band labels typed ✅
A14: Step 3 | B14: Count Each Salary Band | C14: In B2: count employees earning < $40K Copy the pattern down for each band (change the numbers) | D14: =COUNTIFS('Employee Data'!G:G,">=0",'Employee Data'!G:G,"<40000") | E14: Entry band count appears ✅
A15: Step 4 | B15: Average Salary per Band | C15: In C2: calculate average salary ONLY for that band Uses AVERAGEIFS with TWO conditions (low AND high salary boundary) | D15: =AVERAGEIFS('Employee Data'!G:G,'Employee Data'!G:G,">=0",'Employee Data'!G:G,"<40000") | E15: Avg salary per band ✅
A16: Step 5 | B16: Min & Max per Band | C16: D2: =MINIFS('Employee Data'!G:G,'Employee Data'!G:G,">=0",'Employee Data'!G:G,"<40000") E2: =MAXIFS('Employee Data'!G:G,'Employee Data'!G:G,">=0",'Employee Data'!G:G,"<40000") Repeat for all 5 bands — this gives full band range info | D16: =MINIFS('Employee Data'!G:G,'Employee Data'!G:G,">=0",'Employee Data'!G:G,"<40000") | E16: Min & max filled ✅
A17: Step 6 | B17: Top 10 Roles Avg Salary | C17: In column G: list 10 job titles you want to compare In column H: for each title use AVERAGEIF Then sort the table: select G:H → Data → Sort by Column H → Largest to Smallest | D17: =AVERAGEIF('Employee Data'!F:F,G2,'Employee Data'!G:G) | E17: Top roles ranked ✅
A18: Step 7 | B18: Gender × Education Matrix | C18: List unique education levels in column J Column K: count Male employees with that education Column L: count Female employees with that education This becomes your clustered bar chart data | D18: =COUNTIFS('Employee Data'!D:D,J2,'Employee Data'!C:C,"Male") | E18: Gender-edu matrix ✅
A19: Step 8 | B19: Age vs Avg Salary | C19: Column N: list each unique age (20, 21, 22... 65) Column O: average salary for each age group Use AVERAGEIF matching the exact age | D19: =AVERAGEIF('Employee Data'!H:H,N2,'Employee Data'!G:G) | E19: Age-salary data ready ✅
A20: 💡 TIP: AVERAGEIFS, MINIFS, and MAXIFS all follow the same pattern: (value_range, criteria_range1, criteria1, criteria_range2, criteria2). Master these and you can calculate almost any metric!
A22: PHASE 2: KPI CARDS — THE DASHBOARD HEADER
A23: Step 9 | B23: Create Dashboard Sheet | C23: Create a new sheet named 'Employee Dashboard' View tab → uncheck Gridlines for clean look Set tab color: right-click tab → Tab Color → Orange | E23: Dashboard sheet ready ✅
A24: Step 10 | B24: Title Banner | C24: Merge cells A1:N1 Row height: 55 Type your dashboard title Fill: dark color, white text, font size 22, bold Alignment: center both horizontally and vertically | E24: Banner created ✅
A25: Step 11 | B25: KPI Card — Headcount | C25: Merge A5:B5 (label row) and A6:B6 (value row) Label row: 'Headcount', dark blue bg, white text size 10 Value row: =COUNTA('Employee Data'!A:A)-1 White text, font size 18, bold | D25: =COUNTA('Employee Data'!A:A)-1 | E25: Shows 915 ✅
A26: Step 12 | B26: KPI Card — Total Payroll | C26: Merge E5:F5 and E6:F6 Value: =SUM('Employee Data'!G:G) Format as $#,##0 (no cents for large numbers) Fill: green background — signals financial health | D26: =SUM('Employee Data'!G:G) | E26: Total payroll $ ✅
A27: Step 13 | B27: KPI Card — Gender Ratio | C27: Merge M5:N5 and M6:N6 Value formula: =COUNTIF(C:C,"Male")&":"&COUNTIF(C:C,"Female") This concatenates two counts with a colon Good for at-a-glance gender balance check | D27: =COUNTIF('Employee Data'!C:C,"Male")&":"&COUNTIF('Employee Data'!C:C,"Female") | E27: Shows "450:465" ✅
A28: Step 14 | B28: Style All 7 KPI Cards | C28: Each card needs: • Merged label cell: bold, small text, matching background • Merged value cell: large (16–20pt), bold, white text • Different color background per card for variety • Consistent row height (label: 22px, value: 52px) | E28: 7 colorful KPI cards ✅
A29: 💡 TIP: Use CONCATENATE or & to combine text and numbers in KPI cards. Example: ="Total: "&TEXT(SUM(G:G),"$#,##0") creates a formatted string like 'Total: $45,123,000'
A31: PHASE 3: INSERT ALL 4 CHARTS
A32: Step 15 | B32: Chart 1 — Salary Band Column | C32: Go to Summary Data → select A1:B6 (Band + Count) Insert → Column Chart → 2D Clustered Column Move to dashboard sheet → position at A8 Title: 'Headcount by Salary Band' | E32: Chart 1 inserted ✅
A33: Step 16 | B33: Chart 2 — Top 10 Roles Horizontal Bar | C33: Select G1:H11 on Summary Data (Job Title + Avg Salary) Insert → Bar Chart → Horizontal Clustered Bar Move to dashboard → position at J8 (right side) Title: 'Top 10 Roles by Avg Salary' Right-click Y-axis → Format Axis → check 'Categories in reverse order' | E33: Chart 2 inserted ✅
A34: Step 17 | B34: Chart 3 — Gender × Education Clustered | C34: Select J1:L6 (Education + Male + Female columns) Insert → Column Chart → Clustered Column This automatically creates 2 bars side-by-side per education level Title: 'Gender Split by Education Level' Color Male = blue, Female = purple | E34: Chart 3 inserted ✅
A35: Step 18 | B35: Chart 4 — Age vs Salary Line | C35: Select N1:O50 (Age + Avg Salary) Insert → Line Chart → Line with Markers Title: 'Avg Salary Across Age Groups' This reveals the career progression — does salary rise with age? Add a linear trendline to show the overall direction | E35: Chart 4 inserted ✅
A36: Step 19 | B36: Resize & Align Charts | C36: Hold ALT while dragging chart corners — they snap to cell boundaries! Charts 1 & 2 on the same row (top half) Charts 3 & 4 on the next row (bottom half) Make all charts the same height for a uniform look | E36: Charts aligned ✅
A37: 💡 TIP: To set the same size for multiple charts: Ctrl+click each chart → Format tab → enter exact Height and Width values. Professional dashboards use consistent chart sizes!
A39: PHASE 4: SALARY DETAIL TABLE + FINISHING TOUCHES
A40: Step 20 | B40: Build Salary Band Table | C40: Below the charts, create a summary table with headers: Band | Count | Avg Salary | Min Salary | Max Salary Pull values from your Summary Data sheet using cell references Format salary columns as $#,##0.00 | D40: ='Summary Data'!C2 | E40: Table populated ✅
A41: Step 21 | B41: Apply Conditional Formatting to Table | C41: Select the 'Count' column in the table Home → Conditional Formatting → Data Bars → Orange Select 'Avg Salary' column → Color Scale → Green-Yellow-Red Now your table is self-explanatory at a glance! | E41: Visual table created ✅
A42: Step 22 | B42: Add Dashboard Subtitle/Date | C42: Below the title, add a subtitle row: ='Total Employees: '&COUNTA('Employee Data'!A:A)-1&' | Generated: '&TEXT(TODAY(),"MMMM DD, YYYY") Make it light gray italic text — provides context without dominating | D42: =TEXT(TODAY(),"MMMM DD, YYYY") | E42: Date auto-updates ✅
A43: Step 23 | B43: Protect the Dashboard | C43: Review tab → Protect Sheet This prevents accidental editing of formulas and formatting Set a password (optional) and allow: Select unlocked cells, Use slicers Your dashboard is now locked and professional! | E43: Dashboard protected ✅
...

Sheet 🌟 Pro Tips & Tricks
A1: 🌟 PRO EXCEL TIPS & KEYBOARD SHORTCUTS
A3: ⌨️ NAVIGATION SHORTCUTS
B4: Shortcut / Tip | C4: What it Does
B5: Ctrl + Home | C5: Go to cell A1 — the very beginning of the sheet
B6: Ctrl + End | C6: Go to the last used cell in the sheet
B7: Ctrl + Arrow Keys | C7: Jump to the last cell with data in any direction
B8: Ctrl + Shift + End | C8: Select from current cell to last used cell
B9: Ctrl + Page Up/Down | C9: Switch between worksheet tabs
B10: F5 (Go To) | C10: Navigate directly to any cell address or named range
A12: 📝 EDITING SHORTCUTS
B13: Shortcut / Tip | C13: What it Does
B14: Ctrl + Z / Y | C14: Undo / Redo — your best friends!
B15: Ctrl + C / X / V | C15: Copy / Cut / Paste
B16: Ctrl + D | C16: Fill Down — copy formula from cell above to selected range
B17: Ctrl + R | C17: Fill Right — copy formula from left cell to selected range
B18: F2 | C18: Enter edit mode in the active cell
B19: Ctrl + Enter | C19: Enter data in multiple selected cells at once
B20: Alt + Enter | C20: Add a new line WITHIN a cell (instead of moving to next cell)
B21: Ctrl + ; | C21: Insert today's date
B22: Ctrl + Shift + ; | C22: Insert current time
A24: 🎨 FORMATTING SHORTCUTS
B25: Shortcut / Tip | C25: What it Does
B26: Ctrl + 1 | C26: Open Format Cells dialog (quickest way!)
B27: Ctrl + B / I / U | C27: Bold / Italic / Underline
B28: Ctrl + Shift + $ | C28: Apply Currency format instantly
B29: Ctrl + Shift + % | C29: Apply Percentage format instantly
B30: Ctrl + Shift + # | C30: Apply Date format instantly
B31: Alt + H + H | C31: Open cell background color picker
B32: Ctrl + Shift + C/V | C32: Copy / Paste formatting only (Format Painter via keyboard)
A34: 📊 CHART TRICKS
B35: Shortcut / Tip | C35: What it Does
B36: F11 | C36: Create a chart on a NEW sheet from selected data instantly
B37: Alt + F1 | C37: Create a chart EMBEDDED in the current sheet from selected data
B38: Click chart + Delete | C38: Delete a chart quickly
B39: Ctrl + click bars | C39: Select one specific bar/slice to format individually
B40: Double-click axis | C40: Open Format Axis panel
B41: Right-click → Select Data | C41: Change what data the chart uses
A43: 💡 DASHBOARD BEST PRACTICES
B44: Shortcut / Tip | C44: What it Does
B45: Use consistent colors | C45: Pick 2-3 main colors and stick to them throughout
...
