Workbook

Sheet 📋 Estimation Dashboard
B2: 📐 QA RESOURCE & BUDGET ESTIMATION DASHBOARD
B3: ="Project: "&'⚙️ Config'!C5&" | Release: "&'⚙️ Config'!C6&" | QA Lead: "&'⚙️ Config'!C7&" | Est. Date: "&TEXT(TODAY(),"MMM DD, YYYY") -> Project: Phoenix Platform Modernization | Release: Release 3.0 | QA Lead: Jane Smith | Est. Date: May 27, 2026
B4: 📌 Estimation Techniques: PERT | Three-Point | Story Points | Analogy | Use Case Points
B6: 💰 Total QA Budget | I6: 👥 QA Team Size
B7: ='💰 Budget Planner'!J27+'💰 Budget Planner'!J28 -> 407680.35 | I7: ='⚙️ Config'!C12 -> 6
B9: 📅 QA Duration (Wks) | I9: 📋 Est. Test Cases
B10: ='⚙️ Config'!C14 -> 17.3 | I10: ='📝 Test Planning'!C15 -> 74
D12: 📊 ESTIMATION COMPARISON BY TECHNIQUE
D13: Technique | E13: Optimistic | F13: Most Likely | G13: Pessimistic | H13: Estimate | I13: Std Dev | J13: Confidence
D14: PERT (Weighted) | E14: ='📊 PERT Estimation'!E29 -> 229 | F14: ='📊 PERT Estimation'!F29 -> 398 | G14: ='📊 PERT Estimation'!G29 -> 634 | H14: ='📊 PERT Estimation'!H29 -> 409.16667 | I14: ='📊 PERT Estimation'!I29 -> 16.380035 | J14: =TEXT('📊 PERT Estimation'!J29,"0.0")&" – "&TEXT('📊 PERT Estimation'!K29,"0.0") -> 377.1 – 441.3
D15: Three-Point (Triangular) | E15: ='🔺 Three-Point'!E28 -> 229 | F15: ='🔺 Three-Point'!F28 -> 398 | G15: ='🔺 Three-Point'!G28 -> 634 | H15: ='🔺 Three-Point'!H28 -> 420.33333 | I15: ='🔺 Three-Point'!I28 -> 16.3 | J15: =TEXT('🔺 Three-Point'!H28-1.96*'🔺 Three-Point'!I28,"0.0")&" – "&TEXT('🔺 Three-Point'!H28+1.96*'🔺 Three-Point'!I28,"0.0") -> 388.4 – 452.3
D16: Story Points (Agile) | E16: N/A | F16: ='🃏 Story Points'!F24 -> 372.5 | G16: N/A | H16: ='🃏 Story Points'!F24 -> 372.5 | I16: N/A | J16: 🟢 High
D17: Analogy-Based | E17: N/A | F17: ='🔍 Analogy'!E14 -> 322 | G17: N/A | H17: ='🔍 Analogy'!E14 -> 322 | I17: N/A | J17: 🟡 Medium
D18: Use Case Points (UCP) | E18: N/A | F18: ='📐 UCP'!C34 -> 396.9 | G18: N/A | H18: ='📐 UCP'!C34 -> 396.9 | I18: N/A | J18: 🟡 Medium
B20: ⚠️ RISK ADJUSTMENTS | I20: 🎯 RECOMMENDED ESTIMATE
B21: Risk Factor | C21: Level | D21: % of Base | E21: Impact (hrs) | F21: Probability | G21: Expected Impact | I21: =ROUND(AVERAGE('📊 PERT Estimation'!H29,'🔺 Three-Point'!H28),1)&" hrs" -> 414.8 hrs
B22: Unclear Requirements | C22: High | D22: 0.1 | E22: =ROUND(AVERAGE('📊 PERT Estimation'!H29,'🔺 Three-Point'!H28)*0.1,0) -> 41 | F22: 0.6 | G22: =ROUND(E22*F22,1) -> 24.6
B23: New Technology / Tools | C23: Medium | D23: 0.05 | E23: =ROUND(AVERAGE('📊 PERT Estimation'!H29,'🔺 Three-Point'!H28)*0.05,0) -> 21 | F23: 0.4 | G23: =ROUND(E23*F23,1) -> 8.4
B24: Team Skill Gaps | C24: Medium | D24: 0.04 | E24: =ROUND(AVERAGE('📊 PERT Estimation'!H29,'🔺 Three-Point'!H28)*0.04,0) -> 17 | F24: 0.3 | G24: =ROUND(E24*F24,1) -> 5.1 | I24: 💡 WHY THIS ESTIMATE?
B25: Integration Complexity | C25: High | D25: 0.06 | E25: =ROUND(AVERAGE('📊 PERT Estimation'!H29,'🔺 Three-Point'!H28)*0.06,0) -> 25 | F25: 0.5 | G25: =ROUND(E25*F25,1) -> 12.5 | I25: ✅ Average of PERT (409.2) & Three-Point (420.3)
B26: 3rd-Party Dependencies | C26: Low | D26: 0.03 | E26: =ROUND(AVERAGE('📊 PERT Estimation'!H29,'🔺 Three-Point'!H28)*0.03,0) -> 12 | F26: 0.2 | G26: =ROUND(E26*F26,1) -> 2.4 | I26: ✅ Both use same 21 requirements (O/M/P values)
B27: Regulatory / Compliance | C27: Medium | D27: 0.05 | E27: =ROUND(AVERAGE('📊 PERT Estimation'!H29,'🔺 Three-Point'!H28)*0.05,0) -> 21 | F27: 0.3 | G27: =ROUND(E27*F27,1) -> 6.3 | I27: ✅ Reduces single-method estimation bias
B28: Environment Instability | C28: High | D28: 0.07 | E28: =ROUND(AVERAGE('📊 PERT Estimation'!H29,'🔺 Three-Point'!H28)*0.07,0) -> 29 | F28: 0.5 | G28: =ROUND(E28*F28,1) -> 14.5 | I28: ✅ Represents balanced, defensible consensus
B29: 🔺 Total Risk Buffer (hrs) | G29: =ROUND(SUM(G22:G28),1) -> 73.8 | I29: ="⚠️ + Risk Buffer ("&G29&" hrs):" -> ⚠️ + Risk Buffer (73.8 hrs): | L29: =ROUND(AVERAGE('📊 PERT Estimation'!H29,'🔺 Three-Point'!H28)+G29,1)&" hrs" -> 488.6 hrs
I30: 💰 Total QA Budget: | L30: ='💰 Budget Planner'!J27+'💰 Budget Planner'!J28 -> 407680.35
B32: 📘 LEGEND: How Impact (hrs) is Derived
B33: ="Formula: Impact (hrs) = Recommended Estimate ("&ROUND(AVERAGE('📊 PERT Estimation'!H29,'🔺 Three-Point'!H28),1)&" hrs) × % of Base" -> Formula: Impact (hrs) = Recommended Estimate (414.8 hrs) × % of Base
B35: ⚡ Risk Level Definitions:
B36: 🔴 High | C36: 6-10% of base estimate | 50-60% probability | Major impact on schedule/budget
B37: 🟡 Medium | C37: 4-5% of base estimate | 30-40% probability | Moderate impact, manageable
B38: 🟢 Low | C38: 2-3% of base estimate | 10-20% probability | Minor impact, easily mitigated
B40: 📊 Expected Impact Calculation:
B41: Expected Impact = Impact (hrs) × Probability → Total Risk Buffer = Sum of all Expected Impacts
B43: 📊 WHY ESTIMATES DIFFER — STAKEHOLDER FAQ
B44: Why does Story Points (372.5 hrs) show a lower estimate than PERT (409.2 hrs) and Three-Point (420.3 hrs)?
B46: Technique | C46: Estimate | D46: Formula | E46: Uncertainty | F46: Best For | G46: Why Different
B47: PERT (Weighted) | C47: 409.2 | D47: (O+4M+P)/6 | E47: ✅ Includes buffer | F47: Waterfall/Hybrid | G47: Weighted avg adds risk margin
B48: Three-Point (Triangular) | C48: 420.3 | D48: (O+M+P)/3 | E48: ✅ Includes buffer | F48: Waterfall/Hybrid | G48: Most conservative estimate
B49: 🃏 Story Points (Agile) | C49: 372.5 | D49: SP × Hrs/SP | E49: ❌ NO buffer | F49: Agile/Scrum | G49: Direct conversion only
B50: 📐 Use Case Points (UCP) | C50: 396.9 | D50: UCP × 3 hrs | E50: ✅ QA-specific factor | F50: Waterfall/Hybrid | G50: Now aligned with others!
...

Sheet ⚙️ Config
B2: ⚙️ PROJECT CONFIGURATION & TEAM SETUP
B4: 📋 PROJECT INFORMATION
B5: Project Name | C5: Phoenix Platform Modernization | D5: ← Fill in
B6: Release / Version | C6: Release 3.0 | D6: ← Fill in
B7: QA Lead | C7: Jane Smith | D7: ← Fill in
B8: QA Manager | C8: Vishvambruth Javagal | D8: ← Fill in
B9: Start Date | C9: 46174 | D9: YYYY-MM-DD
B10: End Date | C10: 46295 | D10: YYYY-MM-DD
B11: Working Hrs/Day | C11: 8 | D11: hrs
B12: Team Size (QA) | C12: 6 | D12: headcount
B13: Sprint Length | C13: 2 | D13: weeks
B14: QA Duration Wks | C14: =ROUND((C10-C9)/7,1) -> 17.3 | D14: auto-calc
B17: 👥 QA TEAM ROSTER
B18: Name | C18: Role | D18: Skill Level | E18: Rate ($/hr) | F18: Sprint Allocation %
B19: Jane Smith | C19: QA Lead | D19: Senior | E19: 95 | F19: 1
B20: Aisha Patel | C20: Test Analyst | D20: Mid | E20: 70 | F20: 1
B21: Tom Reyes | C21: Automation Eng (UI/API) | D21: Senior | E21: 90 | F21: 0.9
B22: Alex Kim | C22: Mobile Automation Eng | D22: Mid | E22: 75 | F22: 0.9
B23: Carlos Vega | C23: Performance Tester | D23: Mid | E23: 75 | F23: 0.6
B24: Lucy Chen | C24: Junior Tester | D24: Junior | E24: 50 | F24: 0.9
A27: 💡 LEGEND: Cell Colours
B28: 📋 DATA TABLE - HEADERS
B29: ✏️ USER INPUT — fill these cells
B30: 🔢 FORMULA — auto-calculated
B31: 🔒 LABEL — do not edit

Sheet 📊 PERT Estimation
B2: 📊 PERT ESTIMATION — REQUIREMENT-BASED (Single Source of Truth)
B3: Formula: PERT = (O + 4M + P) / 6 | Std Dev = (P - O) / 6 | 95% CI = PERT ± 1.96 × σ
B6: 📋 REQUIREMENT-BASED PERT ESTIMATES (Linked to project requirements)
B7: Module / Functionality | C7: Requirement / User Story | D7: Complexity | E7: Optimistic (O) | F7: Most Likely (M) | G7: Pessimistic (P) | H7: PERT Hrs | I7: Std Dev (σ) | J7: Lower 95% | K7: Upper 95%
B8: User Management | C8: Registration & Login | D8: 🟡 Medium | E8: 12 | F8: 20 | G8: 32 | H8: =(E8+4*F8+G8)/6 -> 20.666667 | I8: =(G8-E8)/6 -> 3.3333333 | J8: =H8-1.96*I8 -> 14.133333 | K8: =H8+1.96*I8 -> 27.2
C9: Password Reset Flow | D9: 🟢 Simple | E9: 7.5 | F9: 12.5 | G9: 20 | H9: =(E9+4*F9+G9)/6 -> 12.916667 | I9: =(G9-E9)/6 -> 2.0833333 | J9: =H9-1.96*I9 -> 8.8333333 | K9: =H9+1.96*I9 -> 17
B10: Product Catalog | C10: Browse & Search | D10: 🟡 Medium | E10: 12 | F10: 20 | G10: 32 | H10: =(E10+4*F10+G10)/6 -> 20.666667 | I10: =(G10-E10)/6 -> 3.3333333 | J10: =H10-1.96*I10 -> 14.133333 | K10: =H10+1.96*I10 -> 27.2
C11: Product Detail Page | D11: 🟡 Medium | E11: 12 | F11: 20 | G11: 32 | H11: =(E11+4*F11+G11)/6 -> 20.666667 | I11: =(G11-E11)/6 -> 3.3333333 | J11: =H11-1.96*I11 -> 14.133333 | K11: =H11+1.96*I11 -> 27.2
C12: Filter & Sort | D12: 🟢 Simple | E12: 7.5 | F12: 12.5 | G12: 20 | H12: =(E12+4*F12+G12)/6 -> 12.916667 | I12: =(G12-E12)/6 -> 2.0833333 | J12: =H12-1.96*I12 -> 8.8333333 | K12: =H12+1.96*I12 -> 17
B13: Cart & Checkout | C13: Add/Remove Cart Items | D13: 🟢 Simple | E13: 7.5 | F13: 12.5 | G13: 20 | H13: =(E13+4*F13+G13)/6 -> 12.916667 | I13: =(G13-E13)/6 -> 2.0833333 | J13: =H13-1.96*I13 -> 8.8333333 | K13: =H13+1.96*I13 -> 17
C14: Checkout Flow | D14: 🔴 Complex | E14: 20 | F14: 40 | G14: 64 | H14: =(E14+4*F14+G14)/6 -> 40.666667 | I14: =(G14-E14)/6 -> 7.3333333 | J14: =H14-1.96*I14 -> 26.293333 | K14: =H14+1.96*I14 -> 55.04
B15: Payment | C15: Order Confirmation | D15: 🟢 Simple | E15: 5 | F15: 10 | G15: 18 | H15: =(E15+4*F15+G15)/6 -> 10.5 | I15: =(G15-E15)/6 -> 2.1666667 | J15: =H15-1.96*I15 -> 6.2533333 | K15: =H15+1.96*I15 -> 14.746667
C16: Credit Card Integration | D16: 🟡 Medium | E16: 12 | F16: 20 | G16: 32 | H16: =(E16+4*F16+G16)/6 -> 20.666667 | I16: =(G16-E16)/6 -> 3.3333333 | J16: =H16-1.96*I16 -> 14.133333 | K16: =H16+1.96*I16 -> 27.2
C17: Refund/Cancellation | D17: 🟢 Simple | E17: 7.5 | F17: 12.5 | G17: 20 | H17: =(E17+4*F17+G17)/6 -> 12.916667 | I17: =(G17-E17)/6 -> 2.0833333 | J17: =H17-1.96*I17 -> 8.8333333 | K17: =H17+1.96*I17 -> 17
B18: Reporting | C18: Dashboard & Charts | D18: 🟡 Medium | E18: 12 | F18: 20 | G18: 32 | H18: =(E18+4*F18+G18)/6 -> 20.666667 | I18: =(G18-E18)/6 -> 3.3333333 | J18: =H18-1.96*I18 -> 14.133333 | K18: =H18+1.96*I18 -> 27.2
C19: Export (CSV/PDF) | D19: 🟢 Simple | E19: 7.5 | F19: 12.5 | G19: 20 | H19: =(E19+4*F19+G19)/6 -> 12.916667 | I19: =(G19-E19)/6 -> 2.0833333 | J19: =H19-1.96*I19 -> 8.8333333 | K19: =H19+1.96*I19 -> 17
B20: Notifications | C20: Email/SMS Alerts | D20: 🟡 Medium | E20: 12 | F20: 20 | G20: 32 | H20: =(E20+4*F20+G20)/6 -> 20.666667 | I20: =(G20-E20)/6 -> 3.3333333 | J20: =H20-1.96*I20 -> 14.133333 | K20: =H20+1.96*I20 -> 27.2
B21: Admin Panel | C21: User Management Admin | D21: 🟡 Medium | E21: 12 | F21: 20 | G21: 32 | H21: =(E21+4*F21+G21)/6 -> 20.666667 | I21: =(G21-E21)/6 -> 3.3333333 | J21: =H21-1.96*I21 -> 14.133333 | K21: =H21+1.96*I21 -> 27.2
C22: Config & Settings | D22: 🟢 Simple | E22: 7.5 | F22: 12.5 | G22: 20 | H22: =(E22+4*F22+G22)/6 -> 12.916667 | I22: =(G22-E22)/6 -> 2.0833333 | J22: =H22-1.96*I22 -> 8.8333333 | K22: =H22+1.96*I22 -> 17
B23: Performance/Security | C23: Load & Stress Testing | D23: 🔴 Complex | E23: 24 | F23: 48 | G23: 72 | H23: =(E23+4*F23+G23)/6 -> 48 | I23: =(G23-E23)/6 -> 8 | J23: =H23-1.96*I23 -> 32.32 | K23: =H23+1.96*I23 -> 63.68
C24: Security Penetration | D24: 🟡 Medium | E24: 12 | F24: 20 | G24: 32 | H24: =(E24+4*F24+G24)/6 -> 20.666667 | I24: =(G24-E24)/6 -> 3.3333333 | J24: =H24-1.96*I24 -> 14.133333 | K24: =H24+1.96*I24 -> 27.2
B25: Regression & Stabilization | C25: Full Regression Suite | D25: 🟡 Medium | E25: 12 | F25: 20 | G25: 32 | H25: =(E25+4*F25+G25)/6 -> 20.666667 | I25: =(G25-E25)/6 -> 3.3333333 | J25: =H25-1.96*I25 -> 14.133333 | K25: =H25+1.96*I25 -> 27.2
C26: Bug Fix Verification | D26: 🟢 Simple | E26: 7.5 | F26: 12.5 | G26: 20 | H26: =(E26+4*F26+G26)/6 -> 12.916667 | I26: =(G26-E26)/6 -> 2.0833333 | J26: =H26-1.96*I26 -> 8.8333333 | K26: =H26+1.96*I26 -> 17
B27: UAT & Release Prep | C27: UAT Support & Fixes | D27: 🟡 Medium | E27: 12 | F27: 20 | G27: 32 | H27: =(E27+4*F27+G27)/6 -> 20.666667 | I27: =(G27-E27)/6 -> 3.3333333 | J27: =H27-1.96*I27 -> 14.133333 | K27: =H27+1.96*I27 -> 27.2
C28: Release Sign-off Testing | D28: 🟢 Simple | E28: 7.5 | F28: 12.5 | G28: 20 | H28: =(E28+4*F28+G28)/6 -> 12.916667 | I28: =(G28-E28)/6 -> 2.0833333 | J28: =H28-1.96*I28 -> 8.8333333 | K28: =H28+1.96*I28 -> 17
B29: TOTALS | E29: =SUM(E8:E28) -> 229 | F29: =SUM(F8:F28) -> 398 | G29: =SUM(G8:G28) -> 634 | H29: =SUM(H8:H28) -> 409.16667 | I29: =SQRT(SUMSQ(I8:I28)) -> 16.380035 | J29: =H29-1.96*I29 -> 377.0618 | K29: =H29+1.96*I29 -> 441.27154
B31: 📌 SUMMARY — SINGLE PERT ESTIMATE (Used by Dashboard)
B32: Total PERT Hours | E32: Std Dev (σ) | G32: Lower 95% CI | I32: Upper 95% CI | K32: Confidence
B33: =H29 -> 409.16667 | E33: =I29 -> 16.380035 | G33: =J29 -> 377.0618 | I33: =K29 -> 441.27154 | K33: 🟢 High
B35: 💡 HOW O/M/P VALUES ARE DERIVED (Waterfall/Hybrid Approach)
B36: In Waterfall/Hybrid projects, O/M/P are estimated directly based on requirement complexity, historical data, and expert judgment.
B38: Estimate Type | C38: Definition | E38: How to Derive | F38: Typical Factors | G38: Example
B39: Optimistic (O) | C39: Best-case scenario | E39: Ideal conditions: clear reqs, no blockers, experienced team | F39: Perfect understanding, no defects, automation available | G39: Login: 12 hrs
B40: Most Likely (M) | C40: Realistic scenario | E40: Based on historical data; typical conditions | F40: Average complexity, some clarifications, standard defects | G40: Login: 20 hrs
B41: Pessimistic (P) | C41: Worst-case scenario | E41: Account for risks: unclear reqs, new tech, rework | F41: High complexity, multiple defect cycles, env issues | G41: Login: 32 hrs
B42: PERT Estimate | C42: (O + 4M + P) / 6 | E42: Weighted average; more weight to Most Likely | F42: 4× weight on M, smooths extremes | G42: (12+80+32)/6 = 20.7 hrs
B44: 📏 ESTIMATION GUIDELINES BY REQUIREMENT COMPLEXITY
B45: Complexity | C45: Characteristics | E45: O (hrs) | F45: M (hrs) | G45: P (hrs) | H45: Ratio (O:M:P)
B46: 🟢 Simple | C46: Clear requirements, standard functionality | E46: 4-8 | F46: 8-16 | G46: 16-24 | H46: 1:2:3
B47: 🟡 Medium | C47: Some integrations, moderate complexity | E47: 8-16 | F47: 16-32 | G47: 32-48 | H47: 1:2:3
...

Sheet 🔺 Three-Point
B2: 🔺 THREE-POINT ESTIMATION — REQUIREMENT-BASED (Triangular Method)
B3: Triangular Formula: (O + M + P) / 3 | Std Dev: (P - O) / 6 | 95% CI = Estimate ± 1.96 × σ
B5: 📋 REQUIREMENT-BASED THREE-POINT ESTIMATES (Triangular Method)
B6: Module / Functionality | C6: Requirement / User Story | D6: Complexity | E6: Optimistic (O) | F6: Most Likely (M) | G6: Pessimistic (P) | H6: Three-Point Est. | I6: Std Dev
B7: User Management | C7: Registration & Login | D7: 🟡 Medium | E7: 12 | F7: 20 | G7: 32 | H7: =(E7+F7+G7)/3 -> 21.333333 | I7: =ROUND((G7-E7)/6,1) -> 3.3
B8: User Management | C8: Password Reset Flow | D8: 🟢 Simple | E8: 7.5 | F8: 12.5 | G8: 20 | H8: =(E8+F8+G8)/3 -> 13.333333 | I8: =ROUND((G8-E8)/6,1) -> 2.1
B9: Product Catalog | C9: Browse & Search | D9: 🟡 Medium | E9: 12 | F9: 20 | G9: 32 | H9: =(E9+F9+G9)/3 -> 21.333333 | I9: =ROUND((G9-E9)/6,1) -> 3.3
B10: Product Catalog | C10: Product Detail Page | D10: 🟡 Medium | E10: 12 | F10: 20 | G10: 32 | H10: =(E10+F10+G10)/3 -> 21.333333 | I10: =ROUND((G10-E10)/6,1) -> 3.3
B11: Product Catalog | C11: Filter & Sort | D11: 🟢 Simple | E11: 7.5 | F11: 12.5 | G11: 20 | H11: =(E11+F11+G11)/3 -> 13.333333 | I11: =ROUND((G11-E11)/6,1) -> 2.1
B12: Cart & Checkout | C12: Add/Remove Cart Items | D12: 🟢 Simple | E12: 7.5 | F12: 12.5 | G12: 20 | H12: =(E12+F12+G12)/3 -> 13.333333 | I12: =ROUND((G12-E12)/6,1) -> 2.1
B13: Cart & Checkout | C13: Checkout Flow | D13: 🔴 Complex | E13: 20 | F13: 40 | G13: 64 | H13: =(E13+F13+G13)/3 -> 41.333333 | I13: =ROUND((G13-E13)/6,1) -> 7.3
B14: Payment | C14: Order Confirmation | D14: 🟢 Simple | E14: 5 | F14: 10 | G14: 18 | H14: =(E14+F14+G14)/3 -> 11 | I14: =ROUND((G14-E14)/6,1) -> 2.2
B15: Payment | C15: Credit Card Integration | D15: 🟡 Medium | E15: 12 | F15: 20 | G15: 32 | H15: =(E15+F15+G15)/3 -> 21.333333 | I15: =ROUND((G15-E15)/6,1) -> 3.3
B16: Payment | C16: Refund/Cancellation | D16: 🟢 Simple | E16: 7.5 | F16: 12.5 | G16: 20 | H16: =(E16+F16+G16)/3 -> 13.333333 | I16: =ROUND((G16-E16)/6,1) -> 2.1
B17: Reporting | C17: Dashboard & Charts | D17: 🟡 Medium | E17: 12 | F17: 20 | G17: 32 | H17: =(E17+F17+G17)/3 -> 21.333333 | I17: =ROUND((G17-E17)/6,1) -> 3.3
B18: Reporting | C18: Export (CSV/PDF) | D18: 🟢 Simple | E18: 7.5 | F18: 12.5 | G18: 20 | H18: =(E18+F18+G18)/3 -> 13.333333 | I18: =ROUND((G18-E18)/6,1) -> 2.1
... B27: UAT & Release Prep | C27: Release Sign-off Testing | D27: 🟢 Simple | E27: 7.5 | F27: 12.5 | G27: 20 | H27: =(E27+F27+G27)/3 -> 13.333333 | I27: =ROUND((G27-E27)/6,1) -> 2.1
B28: TOTALS | E28: =SUM(E7:E27) -> 229 | F28: =SUM(F7:F27) -> 398 | G28: =SUM(G7:G27) -> 634 | H28: =SUM(H7:H27) -> 420.33333 | I28: =ROUND(SQRT(SUMSQ(I7:I27)),1) -> 16.3
B30: 📌 SUMMARY — THREE-POINT ESTIMATE (Triangular Method - Used by Dashboard)
B31: Total Three-Point Hours | F31: Std Dev (σ) | H31: 95% Confidence Interval
B32: =H28 -> 420.33333 | F32: =I28 -> 16.3 | H32: =ROUND(B32-1.96*F32,1)&" – "&ROUND(B32+1.96*F32,1) -> 388.4 – 452.3
B34: 💡 THREE-POINT ESTIMATION METHOD EXPLAINED (Waterfall/Hybrid Approach)
B35: Method | C35: Formula | D35: Description | E35: Best For | F35: When to Use
B36: Triangular (Three-Point) | C36: (O + M + P) / 3 | D36: Equal weight to all estimates | E36: Balanced uncertainty | F36: When O, M, P equally reliable
B39: 📏 ESTIMATION GUIDELINES BY REQUIREMENT COMPLEXITY
B40: Complexity | C40: Characteristics | D40: O (hrs) | E40: M (hrs) | F40: P (hrs) | G40: Ratio (O:M:P)
B41: 🟢 Simple | C41: Clear requirements, standard functionality | D41: 4-8 | E41: 8-16 | F41: 16-24 | G41: 1:2:3
B42: 🟡 Medium | C42: Some integrations, moderate complexity | D42: 8-16 | E42: 16-32 | F42: 32-48 | G42: 1:2:3
B43: 🔴 Complex | C43: Multiple integrations, new tech, high risk | D43: 16-32 | E43: 32-64 | F43: 64-96 | G43: 1:2:3

Sheet 🃏 Story Points
B2: 🃏 STORY POINT ESTIMATION — AGILE / SCRUM
B3: QA Hours = Story Points × Hours-per-Point (velocity) | Fibonacci scale: 1, 2, 3, 5, 8, 13, 21
B5: ⚡ VELOCITY & CAPACITY SETTINGS
B6: Avg. Velocity (SP/sprint) | C6: 40 | D6: ← Team historical average
B7: Sprint Capacity (hrs) | C7: 480 | D7: ← Team size × hrs/day × sprint days
B8: Hours per Story Point (QA) | C8: 2.5 | D8: ← QA hrs per SP (calibrate each project)
B9: Number of Sprints Planned | C9: =ROUND('⚙️ Config'!C14/'⚙️ Config'!C13,0) -> 9 | D9: ← Total planned sprints
B11: 📋 USER STORY ESTIMATES
B12: 📊 EPIC-LEVEL ESTIMATES
B13: Epic Name | C13: Story Points | D13: Priority | E13: Sprint | F13: QA Hrs Est. | G13: Status
B14: Epic: User Management | C14: 13 | D14: High | E14: Sprint 1 | F14: =C14*$C$8 -> 32.5 | G14: Planned
B15: Epic: Product Catalog | C15: 21 | D15: High | E15: Sprint 2 | F15: =C15*$C$8 -> 52.5 | G15: Planned
B16: Epic: Cart & Checkout | C16: 21 | D16: Critical | E16: Sprint 3 | F16: =C16*$C$8 -> 52.5 | G16: Planned
B17: Epic: Payment | C17: 13 | D17: Critical | E17: Sprint 4 | F17: =C17*$C$8 -> 32.5 | G17: Planned
B18: Epic: Reporting | C18: 13 | D18: Medium | E18: Sprint 5 | F18: =C18*$C$8 -> 32.5 | G18: Planned
B19: Epic: Notifications | C19: 8 | D19: Low | E19: Sprint 6 | F19: =C19*$C$8 -> 20 | G19: Planned
B20: Epic: Admin Panel | C20: 13 | D20: Medium | E20: Sprint 6 | F20: =C20*$C$8 -> 32.5 | G20: Planned
B21: Epic: Performance/Security | C21: 21 | D21: High | E21: Sprint 7 | F21: =C21*$C$8 -> 52.5 | G21: Planned
B22: Epic: Regression & Stabilization | C22: 13 | D22: High | E22: Sprint 8 | F22: =C22*$C$8 -> 32.5 | G22: Planned
B23: Epic: UAT & Release Prep | C23: 13 | D23: Critical | E23: Sprint 9 | F23: =C23*$C$8 -> 32.5 | G23: Planned
B24: EPIC TOTALS | C24: =SUM(C14:C23) -> 149 | F24: =SUM(F14:F23) -> 372.5
B26: 📋 USER STORY BREAKDOWN (Must Equal Epic Totals)
B27: Parent Epic | C27: User Story | D27: Story Points | E27: Priority | F27: Sprint | G27: QA Hrs Est. | H27: QA Hrs Actual | I27: Variance | J27: Status
B28: User Management | C28: Registration & Login | D28: 8 | E28: High | F28: Sprint 1 | G28: 20 | J28: To Do
C29: Password Reset Flow | D29: 5 | E29: Medium | F29: Sprint 1 | G29: 12.5 | J29: To Do
B30: Product Catalog | C30: Browse & Search | D30: 8 | E30: High | F30: Sprint 2 | G30: 20 | J30: To Do
C31: Product Detail Page | D31: 8 | E31: High | F31: Sprint 2 | G31: 20 | J31: To Do
C32: Filter & Sort | D32: 5 | E32: Medium | F32: Sprint 2 | G32: 12.5 | J32: To Do
B33: Cart & Checkout | C33: Add/Remove Cart Items | D33: 5 | E33: Critical | F33: Sprint 3 | G33: 12.5 | J33: To Do
C34: Checkout Flow | D34: 13 | E34: Critical | F34: Sprint 3 | G34: 32.5 | J34: To Do
B35: Payment | C35: Order Confirmation | D35: 3 | E35: High | F35: Sprint 4 | G35: 7.5 | J35: To Do
C36: Credit Card Integration | D36: 8 | E36: Critical | F36: Sprint 4 | G36: 20 | J36: To Do
C37: Refund/Cancellation | D37: 5 | E37: High | F37: Sprint 4 | G37: 12.5 | J37: To Do
B38: Reporting | C38: Dashboard & Charts | D38: 8 | E38: Medium | F38: Sprint 5 | G38: 20 | J38: To Do
C39: Export (CSV/PDF) | D39: 5 | E39: Medium | F39: Sprint 5 | G39: 12.5 | J39: To Do
B40: Notifications | C40: Email/SMS Alerts | D40: 8 | E40: Low | F40: Sprint 6 | G40: 20 | J40: To Do
B41: Admin Panel | C41: User Management Admin | D41: 8 | E41: Medium | F41: Sprint 6 | G41: 20 | J41: To Do
C42: Config & Settings | D42: 5 | E42: Medium | F42: Sprint 6 | G42: 12.5 | J42: To Do
B43: Performance/Security | C43: Load & Stress Testing | D43: 13 | E43: High | F43: Sprint 7 | G43: 32.5 | J43: To Do
C44: Security Penetration | D44: 8 | E44: High | F44: Sprint 7 | G44: 20 | J44: To Do
...

Sheet 🔍 Analogy
B2: 🔍 ANALOGY-BASED ESTIMATION
B3: Compare current project to completed reference projects. Adjust using complexity factor.
B5: 📚 REFERENCE PROJECT LIBRARY
B6: Reference Project | C6: QA Hours Actual | D6: Complexity Factor | E6: Adj. Hrs | F6: Similarity %
B7: Project Alpha — E-Commerce v1 | C7: 320 | D7: 1 | E7: =C7*D7 -> 320 | F7: 0.85
B8: Project Beta — Portal Upgrade | C8: 240 | D8: 0.9 | E8: =C8*D8 -> 216 | F8: 0.7
B9: Project Gamma — API Integration | C9: 180 | D9: 1.1 | E9: =C9*D9 -> 198 | F9: 0.6
B10: Project Delta — Mobile App QA | C10: 280 | D10: 1.2 | E10: =C10*D10 -> 336 | F10: 0.75
B11: Project Epsilon — Legacy Mig. | C11: 400 | D11: 1.3 | E11: =C11*D11 -> 520 | F11: 0.5
B12: Project Zeta — Data Platform | C12: 350 | D12: 1.1 | E12: =C12*D12 -> 385 | F12: 0.65
B13: 🎯 WEIGHTED ANALOGY ESTIMATE
B14: Weighted Avg QA Hours | E14: =ROUND(SUMPRODUCT(E7:E12,F7:F12)/SUM(F7:F12),1) -> 322 | F14: =IF(E14<200,"🟢 Low Effort",IF(E14<400,"🟡 Medium","🔴 High Effort")) -> 🟡 Medium

Sheet 📐 UCP
B2: 📐 USE CASE POINT (UCP) ESTIMATION
B3: UCP = (UUCW + UAW) × TCF × ECF | QA Hrs = UCP × Productivity Factor
B5: 📊 USE CASE COMPLEXITY WEIGHTS
B6: Use Case Complexity | C6: Simple (≤3 txns) | D6: Average (4-7) | E6: Complex (>7)
B7: UUCW Weight | C7: 5 | D7: 10 | E7: 15
B8: Actor Complexity | C8: Simple (API) | D8: Average (UI) | E8: Complex (other)
B9: UAW Weight | C9: 1 | D9: 2 | E9: 3
B11: 🧩 USE CASE INVENTORY
B12: Use Case Name | C12: Complexity | D12: UUCW | E12: Actors | F12: UAW | G12: Total UC Points
B13: Login & Authentication | C13: Simple | D13: 5 | E13: Simple | F13: 1 | G13: =D13+F13 -> 6
B14: User Registration | C14: Simple | D14: 5 | E14: Average | F14: 2 | G14: =D14+F14 -> 7
B15: Browse Product Catalog | C15: Average | D15: 10 | E15: Average | F15: 2 | G15: =D15+F15 -> 12
B16: Product Search & Filter | C16: Average | D16: 10 | E16: Average | F16: 2 | G16: =D16+F16 -> 12
B17: Manage Shopping Cart | C17: Average | D17: 10 | E17: Complex | F17: 3 | G17: =D17+F17 -> 13
B18: Checkout Process | C18: Complex | D18: 15 | E18: Complex | F18: 3 | G18: =D18+F18 -> 18
B19: Payment Processing | C19: Complex | D19: 15 | E19: Complex | F19: 3 | G19: =D19+F19 -> 18
B20: Order Tracking | C20: Average | D20: 10 | E20: Average | F20: 2 | G20: =D20+F20 -> 12
B21: Returns & Refunds | C21: Average | D21: 10 | E21: Average | F21: 2 | G21: =D21+F21 -> 12
B22: Generate Sales Reports | C22: Complex | D22: 15 | E22: Average | F22: 2 | G22: =D22+F22 -> 17
B23: Admin: User Management | C23: Average | D23: 10 | E23: Simple | F23: 1 | G23: =D23+F23 -> 11
B24: Admin: Product Management | C24: Average | D24: 10 | E24: Simple | F24: 1 | G24: =D24+F24 -> 11
... B26: View Analytics Dashboard | C26: Complex | D26: 15 | E26: Average | F26: 2 | G26: =D26+F26 -> 17
B27: TOTALS | D27: =SUM(D13:D26) -> 145 | F27: =SUM(F13:F26) -> 28 | G27: =SUM(G13:G26) -> 173
B29: ⚙️ TECHNICAL & ENV. COMPLEXITY FACTORS
B30: TCF (Technical Complexity) | C30: 0.85 | D30: 0.6–1.3 range; lower = more complex
B31: ECF (Environment Complexity) | C31: 0.9 | D31: 0.5–1.4 range; lower = less stable env
B32: UCP (Adjusted) | C32: =ROUND((D27+F27)*C30*C31,1) -> 132.3 | D32: auto-calc
B33: QA Productivity Factor (hrs/UCP) | C33: 3 | D33: ← QA-specific: 2-5 hrs/UCP (Dev uses 15-25)
B34: Total QA Hrs (UCP Method) | C34: =ROUND(C32*C33,1) -> 396.9 | D34: auto-calc
B37: 💡 WHY UCP ESTIMATE DIFFERS & HOW TO CALIBRATE
B38: UCP was originally designed for DEVELOPMENT effort. For QA-only estimation, use a lower productivity factor.
B40: 📊 PRODUCTIVITY FACTOR COMPARISON
B41: Estimation Context | C41: Factor Range | D41: Typical Value | E41: Your UCP (132.3) | F41: Result
B42: Development (Full SDLC) | C42: 15-25 hrs/UCP | D42: 20 hrs/UCP | E42: 132.3 × 20 | F42: 2,646 hrs
B43: QA Only (Recommended) ✅ | C43: 2-5 hrs/UCP | D43: 3 hrs/UCP | E43: 132.3 × 3 | F43: 396.9 hrs
B44: QA + Automation Setup | C44: 5-8 hrs/UCP | D44: 6 hrs/UCP | E44: 132.3 × 6 | F44: 793.8 hrs
B45: QA + Test Design | C45: 8-12 hrs/UCP | D45: 10 hrs/UCP | E45: 132.3 × 10 | F45: 1,323 hrs
B47: 🔑 KEY INSIGHT: Aligning UCP with Other Estimates
B48: Using QA-specific factor (3 hrs/UCP): 132.3 × 3 = 396.9 hrs
B49: This aligns with PERT (409.2 hrs) & Three-Point (420.3 hrs) ✅
...

Sheet 📝 Test Planning
B2: 📝 TEST PLANNING & TEST CASE ESTIMATION
B3: Test Cases = Requirements × Test-to-Req Ratio | Hours = Test Cases × hrs per case
F4: =C15 -> 74
B5: ⚙️ PLANNING PARAMETERS
B6: Total Requirements (User Stories) | C6: =COUNTA('🃏 Story Points'!C28:C48) -> 21 | D6: ← count from backlog
B7: Test-to-Req Ratio | C7: 3.5 | D7: ← avg test cases per requirement
B8: Hrs per Test Case (Design) | C8: 1 | D8: ← estimation standard
B9: Hrs per Test Case (Execution) | C9: 1 | D9: ← estimation standard
B10: Hrs per Test Case (Regression) | C10: 0.5 | D10: ← per regression cycle
B11: Number of Regression Cycles | C11: 3 | D11: ← sprints / releases
B12: Review & Rework Buffer (%) | C12: 0.5 | D12: ← overhead factor
B14: 📊 ESTIMATED OUTPUTS
B15: Estimated Test Cases | C15: =ROUND(C6*C7,0) -> 74
B16: Test Design Hours | C16: =ROUND(C15*C8,1) -> 74
B17: Test Execution Hours | C17: =ROUND(C15*C9,1) -> 74
B18: Regression Hours (total) | C18: =ROUND(C15*C10*C11,1) -> 111
B19: Sub-Total QA Hours | C19: =ROUND(C16+C17+C18,1) -> 259
B20: Review & Rework (buffer) | C20: =ROUND(C19*C12,1) -> 129.5
B21: TOTAL Test Planning Hours | C21: =ROUND(C19+C20,1) -> 388.5

Sheet 💰 Budget Planner
B2: 💰 QA BUDGET PLANNER
B3: Budget = (Team Hours × Hourly Rates) + Tools + Training + Infrastructure + Contingency
B5: 👥 LABOR COST BREAKDOWN
B6: Team Member | C6: Role | D6: Hrs/Sprint | E6: No. Sprints | F6: Total Hrs | G6: $/hr | H6: Labor Cost | I6: Benefits (30%) | J6: Total Cost
B7: Jane Smith | C7: QA Lead | D7: ='⚙️ Config'!$C$11*5*'⚙️ Config'!$C$13*'⚙️ Config'!F19 -> 80 | E7: 9 | F7: =D7*E7 -> 720 | G7: 95 | H7: =F7*G7 -> 68400 | I7: =H7*0.3 -> 20520 | J7: =H7+I7 -> 88920
B8: Aisha Patel | C8: Test Analyst | D8: ='⚙️ Config'!$C$11*5*'⚙️ Config'!$C$13*'⚙️ Config'!F20 -> 80 | E8: 9 | F8: =D8*E8 -> 720 | G8: 70 | H8: =F8*G8 -> 50400 | I8: =H8*0.3 -> 15120 | J8: =H8+I8 -> 65520
B9: Tom Reyes | C9: Automation Eng (UI/API) | D9: ='⚙️ Config'!$C$11*5*'⚙️ Config'!$C$13*'⚙️ Config'!F21 -> 72 | E9: 8 | F9: =D9*E9 -> 576 | G9: 90 | H9: =F9*G9 -> 51840 | I9: =H9*0.3 -> 15552 | J9: =H9+I9 -> 67392
B10: Alex Kim | C10: Mobile Automation Eng | D10: ='⚙️ Config'!$C$11*5*'⚙️ Config'!$C$13*'⚙️ Config'!F22 -> 72 | E10: 8 | F10: =D10*E10 -> 576 | G10: 75 | H10: =F10*G10 -> 43200 | I10: =H10*0.3 -> 12960 | J10: =H10+I10 -> 56160
B11: Carlos Vega | C11: Performance Tester | D11: ='⚙️ Config'!$C$11*5*'⚙️ Config'!$C$13*'⚙️ Config'!F23 -> 48 | E11: 3 | F11: =D11*E11 -> 144 | G11: 75 | H11: =F11*G11 -> 10800 | I11: =H11*0.3 -> 3240 | J11: =H11+I11 -> 14040
B12: Lucy Chen | C12: Junior Tester | D12: ='⚙️ Config'!$C$11*5*'⚙️ Config'!$C$13*'⚙️ Config'!F24 -> 72 | E12: 8 | F12: =D12*E12 -> 576 | G12: 50 | H12: =F12*G12 -> 28800 | I12: =H12*0.3 -> 8640 | J12: =H12+I12 -> 37440
B13: LABOR TOTALS | D13: =SUM(D7:D12) -> 424 | E13: Number of Sprints: 9 | F13: =SUM(F7:F12) -> 3312 | G13: =ROUND(AVERAGE(G7:G12),0) -> 76 | H13: =SUM(H7:H12) -> 253440 | I13: =SUM(I7:I12) -> 76032 | J13: =SUM(J7:J12) -> 329472
B14: 🛠️ TOOLS, INFRASTRUCTURE & OTHER COSTS
B15: Cost Category | C15: Description | D15: Unit Cost | E15: Quantity | F15: Frequency | G15: Total Cost
B16: Test Automation Tools | C16: Selenium/Playwright license | D16: 200 | E16: 3 | F16: 12 | G16: =D16*E16*F16 -> 7200
B17: Test Mgmt Tool | C17: Jira/TestRail subscription | D17: 50 | E17: 5 | F17: 6 | G17: =D17*E17*F17 -> 1500
B18: Performance Tools | C18: JMeter / LoadRunner | D18: 300 | E18: 1 | F18: 1 | G18: =D18*E18*F18 -> 300
B19: Security Tools | C19: OWASP ZAP / BurpSuite | D19: 400 | E19: 1 | F19: 1 | G19: =D19*E19*F19 -> 400
B20: CI/CD Integration | C20: Pipeline setup & maint. | D20: 150 | E20: 1 | F20: 6 | G20: =D20*E20*F20 -> 900
B21: Dev/QA Environment | C21: Cloud infra (AWS/Azure) | D21: 500 | E21: 1 | F21: 6 | G21: =D21*E21*F21 -> 3000
B22: Training | C22: QA skills & tool training | D22: 800 | E22: 2 | F22: 1 | G22: =D22*E22*F22 -> 1600
B23: Travel & Expenses | C23: Onsite visits / stakeholder | D23: 500 | E23: 2 | F23: 1 | G23: =D23*E23*F23 -> 1000
B24: Miscellaneous | C24: 10% buffer for unknowns | D24: 0 | E24: 1 | F24: 1 | G24: =SUM(G16:G23)*0.1 -> 1590
B25: TOTAL NON-LABOR COSTS | G25: =SUM(G16:G24) -> 17490
B27: 💰 TOTAL QA BUDGET | J27: =J13+G25 -> 346962
B28: ⚠️ + Contingency Buffer (recommended 15-20%) | J28: =J27*0.175 -> 60718.35
B29: ✅ FINAL RECOMMENDED QA BUDGET | J29: GRAND TOTAL (with contingency)
J30: =J27+J28 -> 407680.35
M34: =K29 -> 0

Sheet 📅 Sprint Resource Plan
B2: 📅 SPRINT-BY-SPRINT RESOURCE ALLOCATION PLAN
B3: Plan QA headcount and hours per sprint; monitor actuals vs. estimates
B5: 📋 SPRINT ALLOCATION MATRIX
B6: Sprint | C6: Planned Hrs | D6: Actual Hrs | E6: Variance | F6: Variance % | G6: Features In Scope | H6: Test Cases | I6: Pass Rate % | J6: Bugs Found | K6: Status | L6: Team Members Active
B7: Sprint 1 | C7: {=SUMPRODUCT(($G$21:$G$26<=1)*$I$21:$I$26)} -> 160 | D7: 80 | E7: =C7-D7 -> 80 | F7: =IF(C7=0,0,E7/C7) -> 0.5 | K7: =IF(F7>0.1,"⚠️ Under Utilized",IF(F7<-0.05,"🔴 Over Utilized","✅ Utilized")) -> ⚠️ Under Utilized | L7: QA Lead
B8: Sprint 2 | C8: {=SUMPRODUCT(($G$21:$G$26<=2)*$I$21:$I$26)} -> 376 | D8: 376 | E8: =C8-D8 -> 0 | F8: =IF(C8=0,0,E8/C8) -> 0 | K8: =IF(F8>0.1,"⚠️ Under Utilized",IF(F8<-0.05,"🔴 Over Utilized","✅ Utilized")) -> ✅ Utilized | L8: QA Lead, Test Analyst, Automation, Mobile, Manual Tester
B9: Sprint 3 | C9: {=SUMPRODUCT(($G$21:$G$26<=3)*$I$21:$I$26)} -> 376 | D9: 304 | E9: =C9-D9 -> 72 | F9: =IF(C9=0,0,E9/C9) -> 0.19148936 | K9: =IF(F9>0.1,"⚠️ Under Utilized",IF(F9<-0.05,"🔴 Over Utilized","✅ Utilized")) -> ⚠️ Under Utilized | L9: QA Lead, Test Analyst, Automation, Manual Tester
B10: Sprint 4 | C10: {=SUMPRODUCT(($G$21:$G$26<=4)*$I$21:$I$26)} -> 376 | D10: 304 | E10: =C10-D10 -> 72 | F10: =IF(C10=0,0,E10/C10) -> 0.19148936 | K10: =IF(F10>0.1,"⚠️ Under Utilized",IF(F10<-0.05,"🔴 Over Utilized","✅ Utilized")) -> ⚠️ Under Utilized | L10: QA Lead, Test Analyst, Automation, Manual Tester
B11: Sprint 5 | C11: {=SUMPRODUCT(($G$21:$G$26<=5)*$I$21:$I$26)} -> 376 | D11: 376 | E11: =C11-D11 -> 0 | F11: =IF(C11=0,0,E11/C11) -> 0 | K11: =IF(F11>0.1,"⚠️ Under Utilized",IF(F11<-0.05,"🔴 Over Utilized","✅ Utilized")) -> ✅ Utilized | L11: QA Lead, Test Analyst, Automation, Mobile, Manual Tester
B12: Sprint 6 | C12: {=SUMPRODUCT(($G$21:$G$26<=6)*$I$21:$I$26)} -> 376 | D12: 376 | E12: =C12-D12 -> 0 | F12: =IF(C12=0,0,E12/C12) -> 0 | K12: =IF(F12>0.1,"⚠️ Under Utilized",IF(F12<-0.05,"🔴 Over Utilized","✅ Utilized")) -> ✅ Utilized | L12: QA Lead, Test Analyst, Automation, Mobile, Manual Tester
B13: Sprint 7 | C13: {=SUMPRODUCT(($G$21:$G$26<=7)*$I$21:$I$26)} -> 424 | D13: 424 | E13: =C13-D13 -> 0 | F13: =IF(C13=0,0,E13/C13) -> 0 | K13: =IF(F13>0.1,"⚠️ Under Utilized",IF(F13<-0.05,"🔴 Over Utilized","✅ Utilized")) -> ✅ Utilized | L13: QA Lead, Test Analyst, Automation, Mobile, Manual Tester, Perf
B14: Sprint 8 | C14: {=SUMPRODUCT(($G$21:$G$26<=8)*$I$21:$I$26)} -> 424 | D14: 424 | E14: =C14-D14 -> 0 | F14: =IF(C14=0,0,E14/C14) -> 0 | K14: =IF(F14>0.1,"⚠️ Under Utilized",IF(F14<-0.05,"🔴 Over Utilized","✅ Utilized")) -> ✅ Utilized | L14: QA Lead, Test Analyst, Automation, Mobile, Manual Tester, Perf
B15: Sprint 9 | C15: {=SUMPRODUCT(($G$21:$G$26<=9)*$I$21:$I$26)} -> 424 | D15: 424 | E15: =C15-D15 -> 0 | F15: =IF(C15=0,0,E15/C15) -> 0 | K15: =IF(F15>0.1,"⚠️ Under Utilized",IF(F15<-0.05,"🔴 Over Utilized","✅ Utilized")) -> ✅ Utilized | L15: QA Lead, Test Analyst, Automation, Mobile, Manual Tester, Perf
B16: TOTALS | C16: =SUM(C7:C15) -> 3312 | D16: =SUM(D7:D15) -> 3088 | E16: =SUM(E7:E15) -> 224 | F16: =IF(C16=0,0,E16/C16) -> 0.06763285 | I16: =IFERROR(AVERAGE(I7:I14),"")
B19: 👥 TEAM RAMP-UP SCHEDULE
B20: Team Member | C20: Role | D20: Joins Sprint | E20: Ends Sprint | F20: Sprints Active | G20: Join # | H20: Allocation % | I20: Hrs/Sprint
B21: Jane Smith | C21: QA Lead | D21: Sprint 1 | E21: Sprint 9 | F21: 9 (Full project) | G21: 1 | H21: ='⚙️ Config'!F19 -> 1 | I21: ='⚙️ Config'!$C$11*5*'⚙️ Config'!$C$13*H21 -> 80
B22: Aisha Patel | C22: Test Analyst | D22: Sprint 1 | E22: Sprint 9 | F22: 9 (Full project) | G22: 1 | H22: ='⚙️ Config'!F20 -> 1 | I22: ='⚙️ Config'!$C$11*5*'⚙️ Config'!$C$13*H22 -> 80
B23: Tom Reyes | C23: Automation Eng (UI/API) | D23: Sprint 2 | E23: Sprint 9 | F23: 8 (After Sprint 1) | G23: 2 | H23: ='⚙️ Config'!F21 -> 0.9 | I23: ='⚙️ Config'!$C$11*5*'⚙️ Config'!$C$13*H23 -> 72
B24: Alex Kim | C24: Mobile Automation Eng | D24: Sprint 2 | E24: Sprint 9 | F24: 8 (After Sprint 1) | G24: 2 | H24: ='⚙️ Config'!F22 -> 0.9 | I24: ='⚙️ Config'!$C$11*5*'⚙️ Config'!$C$13*H24 -> 72
B25: Carlos Vega | C25: Performance Tester | D25: Sprint 7 | E25: Sprint 9 | F25: 3 (Final sprints) | G25: 7 | H25: ='⚙️ Config'!F23 -> 0.6 | I25: ='⚙️ Config'!$C$11*5*'⚙️ Config'!$C$13*H25 -> 48
B26: Lucy Chen | C26: Manual Tester | D26: Sprint 2 | E26: Sprint 9 | F26: 8 (After Sprint 1) | G26: 2 | H26: ='⚙️ Config'!F24 -> 0.9 | I26: ='⚙️ Config'!$C$11*5*'⚙️ Config'!$C$13*H26 -> 72
B28: 📐 FORMULA EXPLANATION
B29: Planned Hrs Formula: | C29: =SUMPRODUCT(($G$21:$G$26<=SprintNum)*$I$21:$I$26)
B30: Actual Hrs Formula: | C30: =ROUND(Planned*(1-Variance%),0)
B31: Variance Formula: | C31: =Planned Hrs - Actual Hrs
B32: # QA Formula: | C32: =SUMPRODUCT(($G$21:$G$26<=SprintNum)*1)
B34: 💡 TO MODIFY: Change Join # or Allocation % in the Team Ramp-Up table above. All calculations will auto-update!

Sheet 📖 How to Use
B2: 📖 HOW TO USE — QA ESTIMATION TEMPLATE
B4: 🟣 STEP 1 — Configure Your Project | C4: ⚙️ Config sheet
B5: Fill in Project Name, Release, QA Lead, Team roster with roles, skill levels, hourly rates and sprint allocation.
B6: 🟣 STEP 2 — PERT Phase Estimation | C6: 📊 PERT Estimation sheet
B7: Enter Optimistic, Most Likely and Pessimistic hours for each QA phase. PERT and Std Dev calculate automatically.
B8: 🟣 STEP 3 — Feature-Level Three-Point | C8: 🔺 Three-Point sheet
B9: Enter O/M/P hours for each feature or user story. Both PERT and Triangular averages are computed.
B10: 🟣 STEP 4 — Story Points (Agile) | C10: 🃏 Story Points sheet
B11: Assign story points per epic/story. Set velocity and hours-per-point. QA hours auto-calculate.
B12: 🟣 STEP 5 — Analogy Estimation | C12: 🔍 Analogy sheet
B13: Enter reference (past) projects with actual QA hours, complexity factors and similarity %. Weighted estimate is computed.
B14: 🟣 STEP 6 — Use Case Points | C14: 📐 UCP sheet
B15: Log use cases with complexity. Set TCF, ECF and productivity factor. Total QA hours are estimated.
B16: 🟣 STEP 7 — Test Case Planning | C16: 📝 Test Planning sheet
B17: Set requirements count, test-to-req ratio and hrs/case. Total design, execution and regression hours auto-calculate.
B18: 🟣 STEP 8 — Budget Planning | C18: 💰 Budget Planner sheet
B19: Labor costs pull from Config. Add tool, infra and training costs. Final budget with contingency auto-totals.
B20: 🟣 STEP 9 — Risk Buffer | C20: 📋 Dashboard → Risk table
B21: Adjust risk probability and impact on the Dashboard. Total risk buffer adds to recommended estimate.
B22: 🟣 STEP 10 — Sprint Planning | C22: 📅 Sprint Resource Plan sheet
B23: Enter planned hours per sprint and assigned testers. As actuals come in, variance and status update automatically.
B24: 🟣 STEP 11 — Review Dashboard | C24: 📋 Estimation Dashboard
B25: The dashboard aggregates all techniques. Compare side-by-side and use PERT as the primary recommended estimate.
B26: 💡 COLOUR CODE | C26: Dark Green cells = User Input
B27: Dark Blue-Purple = Formula (do not edit) | Purple sections = Section headers
B28: 💡 BEST PRACTICE | C28: Use 2–3 techniques and compare
B29: For new projects: PERT + Story Points. For similar past projects: Analogy. For requirement-heavy: UCP.
B30: 💡 CONFIDENCE | C30: 🟢 High < 10% CV | 🟡 Medium 10–20% | 🔴 Low > 20%
B31: CV = Std Dev / PERT Estimate. Lower is better. Aim for High on critical projects.
